[2015-02-28 10:17:59,798](INFO)kafka : initialized with ip mapping: {'180.97.185.51': '10.20.72.141\n', '180.97.185.50': '10.20.72.153\n', '180.97.185.53': '10.20.72.143\n', '180.97.185.52': '10.20.72.142\n', '180.97.185.55': '10.20.72.144\n', '180.97.185.54': '10.20.72.144\n', '180.97.185.68': '10.20.72.151\n', '180.97.185.69': '10.20.72.152\n', '223.203.199.149': '172.16.10.85\n', '223.203.199.148': '172.16.10.84\n', '223.203.199.152': '172.16.10.97\n', '223.203.199.153': '172.16.10.98\n', '223.203.199.150': '172.16.10.86\n', '223.203.199.151': '172.16.10.96\n', '180.97.185.66': '10.20.72.149\n', '180.97.185.67': '10.20.72.150\n'}
[2015-02-28 10:18:00,801](ERROR)kafka : Unable to connect to kafka broker at 180.97.185.67:9092
Traceback (most recent call last):
  File "build/bdist.linux-x86_64/egg/kafka/conn.py", line 208, in reinit
    self._sock = socket.create_connection((self.host, self.port), self.timeout)
  File "/usr/lib64/python2.7/socket.py", line 571, in create_connection
    raise err
error: [Errno 113] No route to host
[2015-02-28 10:18:00,802](ERROR)kafka : Could not send request [0] to server 180.97.185.67:9092, trying next server
Traceback (most recent call last):
  File "build/bdist.linux-x86_64/egg/kafka/client.py", line 128, in _send_broker_unaware_request
    conn = self._get_conn(host, port)
  File "build/bdist.linux-x86_64/egg/kafka/client.py", line 72, in _get_conn
    timeout=self.timeout
  File "build/bdist.linux-x86_64/egg/kafka/conn.py", line 72, in __init__
    self.reinit()
  File "build/bdist.linux-x86_64/egg/kafka/conn.py", line 211, in reinit
    self._raise_connection_error()
  File "build/bdist.linux-x86_64/egg/kafka/conn.py", line 87, in _raise_connection_error
    raise ConnectionError("Kafka @ {0}:{1} went away".format(self.host, self.port))
ConnectionError: Kafka @ 180.97.185.67:9092 went away
[2015-02-28 10:18:01,805](ERROR)kafka : Unable to connect to kafka broker at 180.97.185.55:9092
Traceback (most recent call last):
  File "build/bdist.linux-x86_64/egg/kafka/conn.py", line 208, in reinit
    self._sock = socket.create_connection((self.host, self.port), self.timeout)
  File "/usr/lib64/python2.7/socket.py", line 571, in create_connection
    raise err
error: [Errno 113] No route to host
[2015-02-28 10:18:01,806](ERROR)kafka : Could not send request [1] to server 180.97.185.55:9092, trying next server
Traceback (most recent call last):
  File "build/bdist.linux-x86_64/egg/kafka/client.py", line 128, in _send_broker_unaware_request
    conn = self._get_conn(host, port)
  File "build/bdist.linux-x86_64/egg/kafka/client.py", line 72, in _get_conn
    timeout=self.timeout
  File "build/bdist.linux-x86_64/egg/kafka/conn.py", line 72, in __init__
    self.reinit()
  File "build/bdist.linux-x86_64/egg/kafka/conn.py", line 211, in reinit
    self._raise_connection_error()
  File "build/bdist.linux-x86_64/egg/kafka/conn.py", line 87, in _raise_connection_error
    raise ConnectionError("Kafka @ {0}:{1} went away".format(self.host, self.port))
ConnectionError: Kafka @ 180.97.185.55:9092 went away
[2015-02-28 10:18:02,809](ERROR)kafka : Unable to connect to kafka broker at 180.97.185.66:9092
Traceback (most recent call last):
  File "build/bdist.linux-x86_64/egg/kafka/conn.py", line 208, in reinit
    self._sock = socket.create_connection((self.host, self.port), self.timeout)
  File "/usr/lib64/python2.7/socket.py", line 571, in create_connection
    raise err
error: [Errno 113] No route to host
[2015-02-28 10:18:02,809](ERROR)kafka : Could not send request [2] to server 180.97.185.66:9092, trying next server
Traceback (most recent call last):
  File "build/bdist.linux-x86_64/egg/kafka/client.py", line 128, in _send_broker_unaware_request
    conn = self._get_conn(host, port)
  File "build/bdist.linux-x86_64/egg/kafka/client.py", line 72, in _get_conn
    timeout=self.timeout
  File "build/bdist.linux-x86_64/egg/kafka/conn.py", line 72, in __init__
    self.reinit()
  File "build/bdist.linux-x86_64/egg/kafka/conn.py", line 211, in reinit
    self._raise_connection_error()
  File "build/bdist.linux-x86_64/egg/kafka/conn.py", line 87, in _raise_connection_error
    raise ConnectionError("Kafka @ {0}:{1} went away".format(self.host, self.port))
ConnectionError: Kafka @ 180.97.185.66:9092 went away
[2015-02-28 10:18:51,508](INFO)kafka : initialized with ip mapping: {'180.97.185.51': '10.20.72.141\n', '180.97.185.50': '10.20.72.153\n', '180.97.185.53': '10.20.72.143\n', '180.97.185.52': '10.20.72.142\n', '180.97.185.55': '10.20.72.144\n', '180.97.185.54': '10.20.72.144\n', '180.97.185.68': '10.20.72.151\n', '180.97.185.69': '10.20.72.152\n', '223.203.199.149': '172.16.10.85\n', '223.203.199.148': '172.16.10.84\n', '223.203.199.152': '172.16.10.97\n', '223.203.199.153': '172.16.10.98\n', '223.203.199.150': '172.16.10.86\n', '223.203.199.151': '172.16.10.96\n', '180.97.185.66': '10.20.72.149\n', '180.97.185.67': '10.20.72.150\n'}
[2015-02-28 10:18:52,509](ERROR)kafka : Unable to connect to kafka broker at 180.97.185.67:9092
Traceback (most recent call last):
  File "build/bdist.linux-x86_64/egg/kafka/conn.py", line 208, in reinit
    self._sock = socket.create_connection((self.host, self.port), self.timeout)
  File "/usr/lib64/python2.7/socket.py", line 571, in create_connection
    raise err
error: [Errno 113] No route to host
[2015-02-28 10:18:52,510](ERROR)kafka : Could not send request [0] to server 180.97.185.67:9092, trying next server
Traceback (most recent call last):
  File "build/bdist.linux-x86_64/egg/kafka/client.py", line 128, in _send_broker_unaware_request
    conn = self._get_conn(host, port)
  File "build/bdist.linux-x86_64/egg/kafka/client.py", line 72, in _get_conn
    timeout=self.timeout
  File "build/bdist.linux-x86_64/egg/kafka/conn.py", line 72, in __init__
    self.reinit()
  File "build/bdist.linux-x86_64/egg/kafka/conn.py", line 211, in reinit
    self._raise_connection_error()
  File "build/bdist.linux-x86_64/egg/kafka/conn.py", line 87, in _raise_connection_error
    raise ConnectionError("Kafka @ {0}:{1} went away".format(self.host, self.port))
ConnectionError: Kafka @ 180.97.185.67:9092 went away
[2015-02-28 10:18:53,513](ERROR)kafka : Unable to connect to kafka broker at 180.97.185.55:9092
Traceback (most recent call last):
  File "build/bdist.linux-x86_64/egg/kafka/conn.py", line 208, in reinit
    self._sock = socket.create_connection((self.host, self.port), self.timeout)
  File "/usr/lib64/python2.7/socket.py", line 571, in create_connection
    raise err
error: [Errno 113] No route to host
[2015-02-28 10:18:53,513](ERROR)kafka : Could not send request [1] to server 180.97.185.55:9092, trying next server
Traceback (most recent call last):
  File "build/bdist.linux-x86_64/egg/kafka/client.py", line 128, in _send_broker_unaware_request
    conn = self._get_conn(host, port)
  File "build/bdist.linux-x86_64/egg/kafka/client.py", line 72, in _get_conn
    timeout=self.timeout
  File "build/bdist.linux-x86_64/egg/kafka/conn.py", line 72, in __init__
    self.reinit()
  File "build/bdist.linux-x86_64/egg/kafka/conn.py", line 211, in reinit
    self._raise_connection_error()
  File "build/bdist.linux-x86_64/egg/kafka/conn.py", line 87, in _raise_connection_error
    raise ConnectionError("Kafka @ {0}:{1} went away".format(self.host, self.port))
ConnectionError: Kafka @ 180.97.185.55:9092 went away
[2015-02-28 10:18:54,517](ERROR)kafka : Unable to connect to kafka broker at 180.97.185.66:9092
Traceback (most recent call last):
  File "build/bdist.linux-x86_64/egg/kafka/conn.py", line 208, in reinit
    self._sock = socket.create_connection((self.host, self.port), self.timeout)
  File "/usr/lib64/python2.7/socket.py", line 571, in create_connection
    raise err
error: [Errno 113] No route to host
[2015-02-28 10:18:54,517](ERROR)kafka : Could not send request [2] to server 180.97.185.66:9092, trying next server
Traceback (most recent call last):
  File "build/bdist.linux-x86_64/egg/kafka/client.py", line 128, in _send_broker_unaware_request
    conn = self._get_conn(host, port)
  File "build/bdist.linux-x86_64/egg/kafka/client.py", line 72, in _get_conn
    timeout=self.timeout
  File "build/bdist.linux-x86_64/egg/kafka/conn.py", line 72, in __init__
    self.reinit()
  File "build/bdist.linux-x86_64/egg/kafka/conn.py", line 211, in reinit
    self._raise_connection_error()
  File "build/bdist.linux-x86_64/egg/kafka/conn.py", line 87, in _raise_connection_error
    raise ConnectionError("Kafka @ {0}:{1} went away".format(self.host, self.port))
ConnectionError: Kafka @ 180.97.185.66:9092 went away
[2015-02-28 10:22:25,563](INFO)kafka : initialized with ip mapping: {'180.97.185.51': '10.20.72.141\n', '180.97.185.50': '10.20.72.153\n', '180.97.185.53': '10.20.72.143\n', '180.97.185.52': '10.20.72.142\n', '180.97.185.55': '10.20.72.144\n', '180.97.185.54': '10.20.72.144\n', '180.97.185.68': '10.20.72.151\n', '180.97.185.69': '10.20.72.152\n', '223.203.199.149': '172.16.10.85\n', '223.203.199.148': '172.16.10.84\n', '223.203.199.152': '172.16.10.97\n', '223.203.199.153': '172.16.10.98\n', '223.203.199.150': '172.16.10.86\n', '223.203.199.151': '172.16.10.96\n', '180.97.185.66': '10.20.72.149\n', '180.97.185.67': '10.20.72.150\n'}
[2015-02-28 10:22:26,565](ERROR)kafka : Unable to connect to kafka broker at 180.97.185.55:9092
Traceback (most recent call last):
  File "build/bdist.linux-x86_64/egg/kafka/conn.py", line 208, in reinit
    self._sock = socket.create_connection((self.host, self.port), self.timeout)
  File "/usr/lib64/python2.7/socket.py", line 571, in create_connection
    raise err
error: [Errno 113] No route to host
[2015-02-28 10:22:26,566](ERROR)kafka : Could not send request [0] to server 180.97.185.55:9092, trying next server
Traceback (most recent call last):
  File "build/bdist.linux-x86_64/egg/kafka/client.py", line 128, in _send_broker_unaware_request
    conn = self._get_conn(host, port)
  File "build/bdist.linux-x86_64/egg/kafka/client.py", line 72, in _get_conn
    timeout=self.timeout
  File "build/bdist.linux-x86_64/egg/kafka/conn.py", line 72, in __init__
    self.reinit()
  File "build/bdist.linux-x86_64/egg/kafka/conn.py", line 211, in reinit
    self._raise_connection_error()
  File "build/bdist.linux-x86_64/egg/kafka/conn.py", line 87, in _raise_connection_error
    raise ConnectionError("Kafka @ {0}:{1} went away".format(self.host, self.port))
ConnectionError: Kafka @ 180.97.185.55:9092 went away
[2015-02-28 10:22:27,569](ERROR)kafka : Unable to connect to kafka broker at 180.97.185.67:9092
Traceback (most recent call last):
  File "build/bdist.linux-x86_64/egg/kafka/conn.py", line 208, in reinit
    self._sock = socket.create_connection((self.host, self.port), self.timeout)
  File "/usr/lib64/python2.7/socket.py", line 571, in create_connection
    raise err
error: [Errno 113] No route to host
[2015-02-28 10:22:27,570](ERROR)kafka : Could not send request [1] to server 180.97.185.67:9092, trying next server
Traceback (most recent call last):
  File "build/bdist.linux-x86_64/egg/kafka/client.py", line 128, in _send_broker_unaware_request
    conn = self._get_conn(host, port)
  File "build/bdist.linux-x86_64/egg/kafka/client.py", line 72, in _get_conn
    timeout=self.timeout
  File "build/bdist.linux-x86_64/egg/kafka/conn.py", line 72, in __init__
    self.reinit()
  File "build/bdist.linux-x86_64/egg/kafka/conn.py", line 211, in reinit
    self._raise_connection_error()
  File "build/bdist.linux-x86_64/egg/kafka/conn.py", line 87, in _raise_connection_error
    raise ConnectionError("Kafka @ {0}:{1} went away".format(self.host, self.port))
ConnectionError: Kafka @ 180.97.185.67:9092 went away
[2015-02-28 10:22:28,573](ERROR)kafka : Unable to connect to kafka broker at 180.97.185.66:9092
Traceback (most recent call last):
  File "build/bdist.linux-x86_64/egg/kafka/conn.py", line 208, in reinit
    self._sock = socket.create_connection((self.host, self.port), self.timeout)
  File "/usr/lib64/python2.7/socket.py", line 571, in create_connection
    raise err
error: [Errno 113] No route to host
[2015-02-28 10:22:28,574](ERROR)kafka : Could not send request [2] to server 180.97.185.66:9092, trying next server
Traceback (most recent call last):
  File "build/bdist.linux-x86_64/egg/kafka/client.py", line 128, in _send_broker_unaware_request
    conn = self._get_conn(host, port)
  File "build/bdist.linux-x86_64/egg/kafka/client.py", line 72, in _get_conn
    timeout=self.timeout
  File "build/bdist.linux-x86_64/egg/kafka/conn.py", line 72, in __init__
    self.reinit()
  File "build/bdist.linux-x86_64/egg/kafka/conn.py", line 211, in reinit
    self._raise_connection_error()
  File "build/bdist.linux-x86_64/egg/kafka/conn.py", line 87, in _raise_connection_error
    raise ConnectionError("Kafka @ {0}:{1} went away".format(self.host, self.port))
ConnectionError: Kafka @ 180.97.185.66:9092 went away
