[2015-02-04 17:17:53,008](INFO)kafka : initialized with ip mapping: {'180.97.185.51': '10.20.72.141\n', '180.97.185.50': '10.20.72.153\n', '180.97.185.53': '10.20.72.143\n', '180.97.185.52': '10.20.72.142\n', '180.97.185.55': '10.20.72.144\n', '180.97.185.54': '10.20.72.144\n', '180.97.185.68': '10.20.72.151\n', '180.97.185.69': '10.20.72.152\n', '223.203.199.149': '172.16.10.85\n', '223.203.199.148': '172.16.10.84\n', '223.203.199.152': '172.16.10.97\n', '223.203.199.153': '172.16.10.98\n', '223.203.199.150': '172.16.10.86\n', '223.203.199.151': '172.16.10.96\n', '180.97.185.66': '10.20.72.149\n', '180.97.185.67': '10.20.72.150\n'}
[2015-02-04 17:17:53,009](ERROR)kafka : Unable to connect to kafka broker at 153.99.250.53:9092
Traceback (most recent call last):
  File "build/bdist.linux-x86_64/egg/kafka/conn.py", line 208, in reinit
    self._sock = socket.create_connection((self.host, self.port), self.timeout)
  File "/usr/lib64/python2.7/socket.py", line 571, in create_connection
    raise err
error: [Errno 111] Connection refused
[2015-02-04 17:17:53,010](ERROR)kafka : Could not send request [0] to server 153.99.250.53:9092, trying next server
Traceback (most recent call last):
  File "build/bdist.linux-x86_64/egg/kafka/client.py", line 128, in _send_broker_unaware_request
    conn = self._get_conn(host, port)
  File "build/bdist.linux-x86_64/egg/kafka/client.py", line 72, in _get_conn
    timeout=self.timeout
  File "build/bdist.linux-x86_64/egg/kafka/conn.py", line 72, in __init__
    self.reinit()
  File "build/bdist.linux-x86_64/egg/kafka/conn.py", line 211, in reinit
    self._raise_connection_error()
  File "build/bdist.linux-x86_64/egg/kafka/conn.py", line 87, in _raise_connection_error
    raise ConnectionError("Kafka @ {0}:{1} went away".format(self.host, self.port))
ConnectionError: Kafka @ 153.99.250.53:9092 went away
[2015-02-04 17:17:53,019](INFO)walle-monitor : kafka hosts: 153.99.250.42:9092,153.99.250.52:9092,153.99.250.53:9092
[2015-02-04 17:17:53,019](INFO)walle-monitor : consumer group: walle-monitor-consumer
[2015-02-04 17:17:53,019](INFO)walle-monitor : topic: zeus-log
[2015-02-04 17:17:53,019](INFO)walle-monitor : consumer type: simple
[2015-02-04 17:17:53,020](INFO)walle-monitor : ip mapping file: /walle-monitor/monitor/config/ipmap.conf
[2015-02-04 17:17:53,020](ERROR)kafka : Unable to connect to kafka broker at 153.99.250.53:9092
Traceback (most recent call last):
  File "build/bdist.linux-x86_64/egg/kafka/conn.py", line 208, in reinit
    self._sock = socket.create_connection((self.host, self.port), self.timeout)
  File "/usr/lib64/python2.7/socket.py", line 571, in create_connection
    raise err
error: [Errno 111] Connection refused
[2015-02-04 17:17:53,021](ERROR)kafka : Could not send request [2] to server 153.99.250.53:9092, trying next server
Traceback (most recent call last):
  File "build/bdist.linux-x86_64/egg/kafka/client.py", line 128, in _send_broker_unaware_request
    conn = self._get_conn(host, port)
  File "build/bdist.linux-x86_64/egg/kafka/client.py", line 72, in _get_conn
    timeout=self.timeout
  File "build/bdist.linux-x86_64/egg/kafka/conn.py", line 72, in __init__
    self.reinit()
  File "build/bdist.linux-x86_64/egg/kafka/conn.py", line 211, in reinit
    self._raise_connection_error()
  File "build/bdist.linux-x86_64/egg/kafka/conn.py", line 87, in _raise_connection_error
    raise ConnectionError("Kafka @ {0}:{1} went away".format(self.host, self.port))
ConnectionError: Kafka @ 153.99.250.53:9092 went away
[2015-02-04 17:17:53,027](INFO)werkzeug :  * Running on http://0.0.0.0:20000/ (Press CTRL+C to quit)
[2015-02-04 17:17:53,027](INFO)walle-monitor : start fetching kafka messages....
[2015-02-04 17:17:53,029](INFO)walle-monitor : start collecting data from fetched message set...
[2015-02-04 17:17:53,030](INFO)walle-monitor : ---------------------------warning set------------------------
[2015-02-04 17:18:23,060](INFO)walle-monitor : start fetching kafka messages....
[2015-02-04 17:18:24,576](INFO)walle-monitor : start collecting data from fetched message set...
[2015-02-04 17:18:24,607](WARNING)walle-monitor : list index out of range
[2015-02-04 17:18:24,796](INFO)walle-monitor : ---------------------------warning set------------------------
[2015-02-04 17:18:55,812](INFO)walle-monitor : start fetching kafka messages....
[2015-02-04 17:19:15,860](INFO)walle-monitor : start collecting data from fetched message set...
[2015-02-04 17:19:15,892](WARNING)walle-monitor : list index out of range
[2015-02-04 17:19:16,147](INFO)walle-monitor : ---------------------------warning set------------------------
[2015-02-04 17:27:16,391](INFO)kafka : initialized with ip mapping: {'180.97.185.51': '10.20.72.141\n', '180.97.185.50': '10.20.72.153\n', '180.97.185.53': '10.20.72.143\n', '180.97.185.52': '10.20.72.142\n', '180.97.185.55': '10.20.72.144\n', '180.97.185.54': '10.20.72.144\n', '180.97.185.68': '10.20.72.151\n', '180.97.185.69': '10.20.72.152\n', '223.203.199.149': '172.16.10.85\n', '223.203.199.148': '172.16.10.84\n', '223.203.199.152': '172.16.10.97\n', '223.203.199.153': '172.16.10.98\n', '223.203.199.150': '172.16.10.86\n', '223.203.199.151': '172.16.10.96\n', '180.97.185.66': '10.20.72.149\n', '180.97.185.67': '10.20.72.150\n'}
[2015-02-04 17:27:16,392](ERROR)kafka : Unable to connect to kafka broker at 153.99.250.53:9092
Traceback (most recent call last):
  File "build/bdist.linux-x86_64/egg/kafka/conn.py", line 208, in reinit
    self._sock = socket.create_connection((self.host, self.port), self.timeout)
  File "/usr/lib64/python2.7/socket.py", line 571, in create_connection
    raise err
error: [Errno 111] Connection refused
[2015-02-04 17:27:16,393](ERROR)kafka : Could not send request [0] to server 153.99.250.53:9092, trying next server
Traceback (most recent call last):
  File "build/bdist.linux-x86_64/egg/kafka/client.py", line 128, in _send_broker_unaware_request
    conn = self._get_conn(host, port)
  File "build/bdist.linux-x86_64/egg/kafka/client.py", line 72, in _get_conn
    timeout=self.timeout
  File "build/bdist.linux-x86_64/egg/kafka/conn.py", line 72, in __init__
    self.reinit()
  File "build/bdist.linux-x86_64/egg/kafka/conn.py", line 211, in reinit
    self._raise_connection_error()
  File "build/bdist.linux-x86_64/egg/kafka/conn.py", line 87, in _raise_connection_error
    raise ConnectionError("Kafka @ {0}:{1} went away".format(self.host, self.port))
ConnectionError: Kafka @ 153.99.250.53:9092 went away
[2015-02-04 17:27:16,400](INFO)walle-monitor : kafka hosts: 153.99.250.42:9092,153.99.250.52:9092,153.99.250.53:9092
[2015-02-04 17:27:16,400](INFO)walle-monitor : consumer group: walle-monitor-consumer
[2015-02-04 17:27:16,400](INFO)walle-monitor : topic: zeus-log
[2015-02-04 17:27:16,400](INFO)walle-monitor : consumer type: simple
[2015-02-04 17:27:16,401](INFO)walle-monitor : ip mapping file: /walle-monitor/monitor/config/ipmap.conf
[2015-02-04 17:27:16,401](ERROR)kafka : Unable to connect to kafka broker at 153.99.250.53:9092
Traceback (most recent call last):
  File "build/bdist.linux-x86_64/egg/kafka/conn.py", line 208, in reinit
    self._sock = socket.create_connection((self.host, self.port), self.timeout)
  File "/usr/lib64/python2.7/socket.py", line 571, in create_connection
    raise err
error: [Errno 111] Connection refused
[2015-02-04 17:27:16,401](ERROR)kafka : Could not send request [2] to server 153.99.250.53:9092, trying next server
Traceback (most recent call last):
  File "build/bdist.linux-x86_64/egg/kafka/client.py", line 128, in _send_broker_unaware_request
    conn = self._get_conn(host, port)
  File "build/bdist.linux-x86_64/egg/kafka/client.py", line 72, in _get_conn
    timeout=self.timeout
  File "build/bdist.linux-x86_64/egg/kafka/conn.py", line 72, in __init__
    self.reinit()
  File "build/bdist.linux-x86_64/egg/kafka/conn.py", line 211, in reinit
    self._raise_connection_error()
  File "build/bdist.linux-x86_64/egg/kafka/conn.py", line 87, in _raise_connection_error
    raise ConnectionError("Kafka @ {0}:{1} went away".format(self.host, self.port))
ConnectionError: Kafka @ 153.99.250.53:9092 went away
[2015-02-04 17:27:16,461](INFO)werkzeug :  * Running on http://0.0.0.0:20000/ (Press CTRL+C to quit)
[2015-02-04 17:27:16,461](INFO)walle-monitor : start fetching kafka messages....
[2015-02-04 17:27:16,500](INFO)walle-monitor : start collecting data from fetched message set...
[2015-02-04 17:27:16,501](INFO)walle-monitor : ---------------------------warning set------------------------
[2015-02-04 17:27:50,177](INFO)kafka : initialized with ip mapping: {'180.97.185.51': '10.20.72.141\n', '180.97.185.50': '10.20.72.153\n', '180.97.185.53': '10.20.72.143\n', '180.97.185.52': '10.20.72.142\n', '180.97.185.55': '10.20.72.144\n', '180.97.185.54': '10.20.72.144\n', '180.97.185.68': '10.20.72.151\n', '180.97.185.69': '10.20.72.152\n', '223.203.199.149': '172.16.10.85\n', '223.203.199.148': '172.16.10.84\n', '223.203.199.152': '172.16.10.97\n', '223.203.199.153': '172.16.10.98\n', '223.203.199.150': '172.16.10.86\n', '223.203.199.151': '172.16.10.96\n', '180.97.185.66': '10.20.72.149\n', '180.97.185.67': '10.20.72.150\n'}
[2015-02-04 17:27:50,206](INFO)walle-monitor : kafka hosts: 153.99.250.42:9092,153.99.250.52:9092,153.99.250.53:9092
[2015-02-04 17:27:50,206](INFO)walle-monitor : consumer group: walle-monitor-consumer
[2015-02-04 17:27:50,206](INFO)walle-monitor : topic: zeus-log
[2015-02-04 17:27:50,206](INFO)walle-monitor : consumer type: simple
[2015-02-04 17:27:50,206](INFO)walle-monitor : ip mapping file: /walle-monitor/monitor/config/ipmap.conf
[2015-02-04 17:27:50,281](INFO)werkzeug :  * Running on http://0.0.0.0:20000/ (Press CTRL+C to quit)
[2015-02-04 17:27:50,281](INFO)walle-monitor : start fetching kafka messages....
[2015-02-04 17:27:50,332](INFO)walle-monitor : start collecting data from fetched message set...
[2015-02-04 17:27:50,332](INFO)walle-monitor : ---------------------------warning set------------------------
[2015-02-04 17:28:20,362](INFO)walle-monitor : start fetching kafka messages....
[2015-02-04 17:28:21,334](INFO)walle-monitor : start collecting data from fetched message set...
[2015-02-04 17:28:21,334](WARNING)walle-monitor : list index out of range
[2015-02-04 17:28:21,378](WARNING)walle-monitor : list index out of range
[2015-02-04 17:28:21,390](WARNING)walle-monitor : list index out of range
[2015-02-04 17:28:21,554](INFO)walle-monitor : ---------------------------warning set------------------------
[2015-02-04 17:30:22,122](INFO)kafka : initialized with ip mapping: {'180.97.185.51': '10.20.72.141\n', '180.97.185.50': '10.20.72.153\n', '180.97.185.53': '10.20.72.143\n', '180.97.185.52': '10.20.72.142\n', '180.97.185.55': '10.20.72.144\n', '180.97.185.54': '10.20.72.144\n', '180.97.185.68': '10.20.72.151\n', '180.97.185.69': '10.20.72.152\n', '223.203.199.149': '172.16.10.85\n', '223.203.199.148': '172.16.10.84\n', '223.203.199.152': '172.16.10.97\n', '223.203.199.153': '172.16.10.98\n', '223.203.199.150': '172.16.10.86\n', '223.203.199.151': '172.16.10.96\n', '180.97.185.66': '10.20.72.149\n', '180.97.185.67': '10.20.72.150\n'}
[2015-02-04 17:30:22,123](ERROR)kafka : Unable to connect to kafka broker at 153.99.250.53:9092
Traceback (most recent call last):
  File "build/bdist.linux-x86_64/egg/kafka/conn.py", line 208, in reinit
    self._sock = socket.create_connection((self.host, self.port), self.timeout)
  File "/usr/lib64/python2.7/socket.py", line 571, in create_connection
    raise err
error: [Errno 111] Connection refused
[2015-02-04 17:30:22,124](ERROR)kafka : Could not send request [0] to server 153.99.250.53:9092, trying next server
Traceback (most recent call last):
  File "build/bdist.linux-x86_64/egg/kafka/client.py", line 128, in _send_broker_unaware_request
    conn = self._get_conn(host, port)
  File "build/bdist.linux-x86_64/egg/kafka/client.py", line 72, in _get_conn
    timeout=self.timeout
  File "build/bdist.linux-x86_64/egg/kafka/conn.py", line 72, in __init__
    self.reinit()
  File "build/bdist.linux-x86_64/egg/kafka/conn.py", line 211, in reinit
    self._raise_connection_error()
  File "build/bdist.linux-x86_64/egg/kafka/conn.py", line 87, in _raise_connection_error
    raise ConnectionError("Kafka @ {0}:{1} went away".format(self.host, self.port))
ConnectionError: Kafka @ 153.99.250.53:9092 went away
[2015-02-04 17:30:22,131](INFO)walle-monitor : kafka hosts: 153.99.250.42:9092,153.99.250.52:9092,153.99.250.53:9092
[2015-02-04 17:30:22,131](INFO)walle-monitor : consumer group: walle-monitor-consumer
[2015-02-04 17:30:22,131](INFO)walle-monitor : topic: zeus-log
[2015-02-04 17:30:22,131](INFO)walle-monitor : consumer type: simple
[2015-02-04 17:30:22,132](INFO)walle-monitor : ip mapping file: /walle-monitor/monitor/config/ipmap.conf
[2015-02-04 17:30:22,132](ERROR)kafka : Unable to connect to kafka broker at 153.99.250.53:9092
Traceback (most recent call last):
  File "build/bdist.linux-x86_64/egg/kafka/conn.py", line 208, in reinit
    self._sock = socket.create_connection((self.host, self.port), self.timeout)
  File "/usr/lib64/python2.7/socket.py", line 571, in create_connection
    raise err
error: [Errno 111] Connection refused
[2015-02-04 17:30:22,133](ERROR)kafka : Could not send request [2] to server 153.99.250.53:9092, trying next server
Traceback (most recent call last):
  File "build/bdist.linux-x86_64/egg/kafka/client.py", line 128, in _send_broker_unaware_request
    conn = self._get_conn(host, port)
  File "build/bdist.linux-x86_64/egg/kafka/client.py", line 72, in _get_conn
    timeout=self.timeout
  File "build/bdist.linux-x86_64/egg/kafka/conn.py", line 72, in __init__
    self.reinit()
  File "build/bdist.linux-x86_64/egg/kafka/conn.py", line 211, in reinit
    self._raise_connection_error()
  File "build/bdist.linux-x86_64/egg/kafka/conn.py", line 87, in _raise_connection_error
    raise ConnectionError("Kafka @ {0}:{1} went away".format(self.host, self.port))
ConnectionError: Kafka @ 153.99.250.53:9092 went away
[2015-02-04 17:30:22,135](INFO)walle-monitor : start fetching kafka messages....
[2015-02-04 17:30:22,137](INFO)werkzeug :  * Running on http://0.0.0.0:20000/ (Press CTRL+C to quit)
[2015-02-04 17:30:22,138](INFO)walle-monitor : start collecting data from fetched message set...
[2015-02-04 17:30:22,139](INFO)walle-monitor : ---------------------------warning set------------------------
[2015-02-04 17:30:52,169](INFO)walle-monitor : start fetching kafka messages....
[2015-02-04 17:30:52,888](INFO)walle-monitor : start collecting data from fetched message set...
[2015-02-04 17:30:52,890](WARNING)walle-monitor : list index out of range
[2015-02-04 17:30:53,106](INFO)walle-monitor : ---------------------------warning set------------------------
[2015-02-04 17:31:24,441](INFO)walle-monitor : start fetching kafka messages....
[2015-02-04 17:31:25,003](INFO)walle-monitor : start collecting data from fetched message set...
[2015-02-04 17:31:25,005](WARNING)walle-monitor : list index out of range
[2015-02-04 17:31:25,059](WARNING)walle-monitor : list index out of range
[2015-02-04 17:31:25,255](INFO)walle-monitor : ---------------------------warning set------------------------
[2015-02-04 17:35:04,387](INFO)kafka : initialized with ip mapping: {'180.97.185.51': '10.20.72.141\n', '180.97.185.50': '10.20.72.153\n', '180.97.185.53': '10.20.72.143\n', '180.97.185.52': '10.20.72.142\n', '180.97.185.55': '10.20.72.144\n', '180.97.185.54': '10.20.72.144\n', '180.97.185.68': '10.20.72.151\n', '180.97.185.69': '10.20.72.152\n', '223.203.199.149': '172.16.10.85\n', '223.203.199.148': '172.16.10.84\n', '223.203.199.152': '172.16.10.97\n', '223.203.199.153': '172.16.10.98\n', '223.203.199.150': '172.16.10.86\n', '223.203.199.151': '172.16.10.96\n', '180.97.185.66': '10.20.72.149\n', '180.97.185.67': '10.20.72.150\n'}
[2015-02-04 17:35:04,394](INFO)walle-monitor : kafka hosts: 153.99.250.42:9092,153.99.250.52:9092,153.99.250.53:9092
[2015-02-04 17:35:04,395](INFO)walle-monitor : consumer group: walle-monitor-consumer
[2015-02-04 17:35:04,395](INFO)walle-monitor : topic: zeus-log
[2015-02-04 17:35:04,395](INFO)walle-monitor : consumer type: simple
[2015-02-04 17:35:04,395](INFO)walle-monitor : ip mapping file: /walle-monitor/monitor/config/ipmap.conf
[2015-02-04 17:35:04,400](INFO)werkzeug :  * Running on http://0.0.0.0:20000/ (Press CTRL+C to quit)
[2015-02-04 17:35:04,400](INFO)walle-monitor : start fetching kafka messages....
[2015-02-04 17:35:04,402](INFO)walle-monitor : start collecting data from fetched message set...
[2015-02-04 17:35:04,402](INFO)walle-monitor : ---------------------------warning set------------------------
[2015-02-04 17:35:34,433](INFO)walle-monitor : start fetching kafka messages....
[2015-02-04 17:35:36,136](INFO)walle-monitor : start collecting data from fetched message set...
[2015-02-04 17:35:36,188](WARNING)walle-monitor : list index out of range
[2015-02-04 17:35:36,354](INFO)walle-monitor : ---------------------------warning set------------------------
[2015-02-04 17:37:50,056](INFO)kafka : initialized with ip mapping: {'180.97.185.51': '10.20.72.141\n', '180.97.185.50': '10.20.72.153\n', '180.97.185.53': '10.20.72.143\n', '180.97.185.52': '10.20.72.142\n', '180.97.185.55': '10.20.72.144\n', '180.97.185.54': '10.20.72.144\n', '180.97.185.68': '10.20.72.151\n', '180.97.185.69': '10.20.72.152\n', '223.203.199.149': '172.16.10.85\n', '223.203.199.148': '172.16.10.84\n', '223.203.199.152': '172.16.10.97\n', '223.203.199.153': '172.16.10.98\n', '223.203.199.150': '172.16.10.86\n', '223.203.199.151': '172.16.10.96\n', '180.97.185.66': '10.20.72.149\n', '180.97.185.67': '10.20.72.150\n'}
[2015-02-04 17:37:50,057](ERROR)kafka : Unable to connect to kafka broker at 153.99.250.53:9092
Traceback (most recent call last):
  File "build/bdist.linux-x86_64/egg/kafka/conn.py", line 208, in reinit
    self._sock = socket.create_connection((self.host, self.port), self.timeout)
  File "/usr/lib64/python2.7/socket.py", line 571, in create_connection
    raise err
error: [Errno 111] Connection refused
[2015-02-04 17:37:50,058](ERROR)kafka : Could not send request [0] to server 153.99.250.53:9092, trying next server
Traceback (most recent call last):
  File "build/bdist.linux-x86_64/egg/kafka/client.py", line 128, in _send_broker_unaware_request
    conn = self._get_conn(host, port)
  File "build/bdist.linux-x86_64/egg/kafka/client.py", line 72, in _get_conn
    timeout=self.timeout
  File "build/bdist.linux-x86_64/egg/kafka/conn.py", line 72, in __init__
    self.reinit()
  File "build/bdist.linux-x86_64/egg/kafka/conn.py", line 211, in reinit
    self._raise_connection_error()
  File "build/bdist.linux-x86_64/egg/kafka/conn.py", line 87, in _raise_connection_error
    raise ConnectionError("Kafka @ {0}:{1} went away".format(self.host, self.port))
ConnectionError: Kafka @ 153.99.250.53:9092 went away
[2015-02-04 17:37:50,065](INFO)walle-monitor : kafka hosts: 153.99.250.42:9092,153.99.250.52:9092,153.99.250.53:9092
[2015-02-04 17:37:50,065](INFO)walle-monitor : consumer group: walle-monitor-consumer
[2015-02-04 17:37:50,065](INFO)walle-monitor : topic: zeus-log
[2015-02-04 17:37:50,065](INFO)walle-monitor : consumer type: simple
[2015-02-04 17:37:50,066](INFO)walle-monitor : ip mapping file: /walle-monitor/monitor/config/ipmap.conf
[2015-02-04 17:37:50,066](ERROR)kafka : Unable to connect to kafka broker at 153.99.250.53:9092
Traceback (most recent call last):
  File "build/bdist.linux-x86_64/egg/kafka/conn.py", line 208, in reinit
    self._sock = socket.create_connection((self.host, self.port), self.timeout)
  File "/usr/lib64/python2.7/socket.py", line 571, in create_connection
    raise err
error: [Errno 111] Connection refused
[2015-02-04 17:37:50,066](ERROR)kafka : Could not send request [2] to server 153.99.250.53:9092, trying next server
Traceback (most recent call last):
  File "build/bdist.linux-x86_64/egg/kafka/client.py", line 128, in _send_broker_unaware_request
    conn = self._get_conn(host, port)
  File "build/bdist.linux-x86_64/egg/kafka/client.py", line 72, in _get_conn
    timeout=self.timeout
  File "build/bdist.linux-x86_64/egg/kafka/conn.py", line 72, in __init__
    self.reinit()
  File "build/bdist.linux-x86_64/egg/kafka/conn.py", line 211, in reinit
    self._raise_connection_error()
  File "build/bdist.linux-x86_64/egg/kafka/conn.py", line 87, in _raise_connection_error
    raise ConnectionError("Kafka @ {0}:{1} went away".format(self.host, self.port))
ConnectionError: Kafka @ 153.99.250.53:9092 went away
[2015-02-04 17:37:50,118](INFO)werkzeug :  * Running on http://0.0.0.0:20000/ (Press CTRL+C to quit)
[2015-02-04 17:37:50,118](INFO)walle-monitor : start fetching kafka messages....
[2015-02-04 17:37:50,201](INFO)walle-monitor : start collecting data from fetched message set...
[2015-02-04 17:37:50,202](INFO)walle-monitor : ---------------------------warning set------------------------
[2015-02-04 17:38:20,232](INFO)walle-monitor : start fetching kafka messages....
[2015-02-04 17:38:21,063](INFO)walle-monitor : start collecting data from fetched message set...
[2015-02-04 17:38:21,077](WARNING)walle-monitor : list index out of range
[2015-02-04 17:38:21,277](INFO)walle-monitor : ---------------------------warning set------------------------
[2015-02-04 17:38:52,341](INFO)walle-monitor : start fetching kafka messages....
[2015-02-04 17:38:53,198](INFO)walle-monitor : start collecting data from fetched message set...
[2015-02-04 17:38:53,210](WARNING)walle-monitor : list index out of range
[2015-02-04 17:38:53,442](INFO)walle-monitor : ---------------------------warning set------------------------
[2015-02-04 17:39:23,482](INFO)walle-monitor : start fetching kafka messages....
[2015-02-04 17:39:25,230](INFO)walle-monitor : start collecting data from fetched message set...
[2015-02-04 17:39:25,243](WARNING)walle-monitor : list index out of range
[2015-02-04 17:39:25,465](INFO)walle-monitor : ---------------------------warning set------------------------
